Workbook

Sheet Balance
A1: ESTADO DE SITUACIÓN PATRIMONIAL · Andina Manufacturas S.A. (en miles de USD)
A2: Drill-down: usá los botones [+]/[−] del margen izquierdo para abrir o cerrar rubros, subrubros y cuentas. Editá SOLO las celdas amarillas (cuentas).
A4: ACTIVO | B4: =B5+B24
A5: Activo Corriente | B5: =B6+B10+B12+B15+B19
A6: Caja y Bancos | B6: =SUM(B7:B9)
A7: Caja | B7: 40
A8: Banco cuenta corriente $ | B8: 90
A9: Banco cuenta USD | B9: 50
A10: Inversiones transitorias | B10: =SUM(B11:B11)
A11: Plazo fijo | B11: 60
A12: Créditos por ventas | B12: =SUM(B13:B14)
A13: Deudores por ventas | B13: 1560
A14: Documentos a cobrar (mora >120d) | B14: 290 | D14: Alta probabilidad de incobrabilidad.
A15: Otros créditos | B15: =SUM(B16:B18)
A16: IVA crédito fiscal | B16: 180
A17: Anticipos a proveedores | B17: 90
A18: Gastos pagados por adelantado | B18: 50
A19: Bienes de cambio (inventarios) | B19: =SUM(B20:B23)
A20: Materia prima | B20: 700
A21: Productos en proceso | B21: 480
A22: Productos terminados | B22: 800
A23: Mercadería de lenta rotación | B23: 420 | D23: Obsoleta: a mercado vale menos.
A24: Activo No Corriente | B24: =B25+B27+B30+B33
A25: Bienes de Uso — Terrenos | B25: =SUM(B26:B26)
A26: Terreno planta industrial | B26: 350
A27: Bienes de Uso — Edificios | B27: =SUM(B28:B29)
A28: Edificio (costo) | B28: 800
A29: Amortización acumulada edificio | B29: -180
A30: Bienes de Uso — Maquinaria | B30: =SUM(B31:B32)
A31: Maquinaria (costo) | B31: 2100
A32: Amortización acumulada maquinaria | B32: -650
A33: Bienes de Uso — Rodados | B33: =SUM(B34:B35)
A34: Rodados (costo) | B34: 260
A35: Amortización acumulada rodados | B35: -120
A36: PASIVO | B36: =B37+B48
A37: Pasivo Corriente | B37: =B38+B41+B44
A38: Deudas bancarias corto plazo | B38: =SUM(B39:B40)
A39: Descubierto bancario | B39: 540 | D39: Producto caro (TNA ~85%).
A40: Préstamo bancario corto plazo | B40: 620
A41: Deudas comerciales | B41: =SUM(B42:B43)
...

Sheet Resultados
A1: ESTADO DE RESULTADOS · Andina Manufacturas S.A. (en miles de USD)
A2: Drill-down por línea. Editá las cuentas (amarillo). Los subtotales y los resultados intermedios se calculan solos.
A4: Ventas netas | B4: =SUM(B5:B6)
A5: Ventas de productos | B5: 8000
A6: Ventas de servicios | B6: 200
A7: Costo de mercadería vendida | B7: =SUM(B8:B10)
A8: Materia prima consumida | B8: -3200
A9: Mano de obra directa | B9: -1600
A10: Costos indirectos de fabricación | B10: -940
A11: RESULTADO BRUTO | B11: =B4+B7
A12: Gastos de comercialización | B12: =SUM(B13:B15)
A13: Comisiones de venta | B13: -300
A14: Fletes y distribución | B14: -200
A15: Publicidad | B15: -300
A16: Gastos de administración | B16: =SUM(B17:B19)
A17: Sueldos administración | B17: -300
A18: Honorarios profesionales | B18: -140
A19: Otros gastos | B19: -100
A20: EBITDA | B20: =B11+B12+B16
A21: Amortizaciones | B21: =SUM(B22:B22)
A22: Amortización de bienes de uso | B22: -290
A23: EBIT (resultado operativo) | B23: =B20+B21
A24: Resultados financieros | B24: =SUM(B25:B27)
A25: Intereses de préstamos | B25: -300
A26: Intereses de descubierto | B26: -200
A27: Comisiones bancarias | B27: -60
A28: RESULTADO ANTES DE IMPUESTOS | B28: =B23+B24
A29: Impuesto a las ganancias | B29: =SUM(B30:B30)
A30: Impuesto a las ganancias (35%) | B30: -95
A31: RESULTADO DEL EJERCICIO | B31: =B28+B29
A33: ="El RESULTADO DEL EJERCICIO ("&TEXT(B31,"#,##0")&" k) se traslada al Patrimonio Neto del Balance. Ver la hoja Articulacion."

Sheet Articulacion
A1: ARTICULACIÓN: cómo el Resultado del Ejercicio cierra la PARTIDA DOBLE
B3: ESTADO DE RESULTADOS — Resultado del Ejercicio | E3: TOTAL ACTIVO (lo que la empresa tiene)
C4: =Resultados!B31 | F4: =Balance!B4
B6: ⬇ | C6: El resultado del ejercicio NO se queda en el Estado de Resultados: se capitaliza. | E6: ⬅⮕ | F6: Tiene que ser igual a...
B8: PATRIMONIO NETO — incluye el Resultado del Ejercicio | E8: PASIVO + PATRIMONIO NETO (cómo se financió)
C9: =Balance!B54 | F9: =Balance!B36+Balance!B53
B11: ⬇ | C11: El Patrimonio Neto es una parte del lado derecho del Balance (lo que es de los dueños).
B13: ="ACTIVO ("&TEXT(Balance!B4,"#,##0")&") = PASIVO ("&TEXT(Balance!B36,"#,##0")&") + PATRIMONIO NETO ("&TEXT(Balance!B53,"#,##0")&")"
B15: =IF(ABS(Balance!B67)<1,"✔ La partida doble CIERRA. Cada peso del activo esta financiado por terceros (pasivo) o por los duenos (patrimonio neto), y el resultado del ejercicio aumenta el patrimonio.","✖ Hay un descalce de "&TEXT(Balance!B67,"#,##0")&" k: alguna cuenta no fue registrada por partida doble.")

Sheet Indicadores
A1: INDICADORES — cada caja se vincula (➜) a las magnitudes del Balance y del Estado de Resultados
A3: LIQUIDEZ
A4: Indicador | B4: Valor | C4: Cómo se construye (➜ magnitudes vinculadas)
A5: Liquidez corriente | B5: =Balance!B5/Balance!B37 | C5: ➜ Activo Corriente ÷ Pasivo Corriente
A6: Liquidez ácida (prueba del ácido) | B6: =(Balance!B5-Balance!B19)/Balance!B37 | C6: ➜ (Activo Corriente − Inventarios) ÷ Pasivo Corriente
A7: Liquidez de caja | B7: =(Balance!B6+Balance!B10)/Balance!B37 | C7: ➜ (Caja y Bancos + Inversiones) ÷ Pasivo Corriente
A8: Capital de trabajo | B8: =Balance!B5-Balance!B37 | C8: ➜ Activo Corriente − Pasivo Corriente
A9: SOLVENCIA
A10: Indicador | B10: Valor | C10: Cómo se construye (➜ magnitudes vinculadas)
A11: Endeudamiento (Pasivo/Activo) | B11: =Balance!B36/Balance!B4 | C11: ➜ Pasivo Total ÷ Activo Total
A12: Deuda / Patrimonio Neto | B12: =Balance!B36/Balance!B53 | C12: ➜ Pasivo Total ÷ Patrimonio Neto
A13: Solvencia (Activo/Pasivo) | B13: =Balance!B4/Balance!B36 | C13: ➜ Activo Total ÷ Pasivo Total
A14: Inmovilización del activo | B14: =Balance!B24/Balance!B4 | C14: ➜ Activo No Corriente ÷ Activo Total
A15: ECONÓMICOS (rentabilidad)
A16: Indicador | B16: Valor | C16: Cómo se construye (➜ magnitudes vinculadas)
A17: Margen bruto | B17: =Resultados!B11/Resultados!B4 | C17: ➜ Resultado Bruto ÷ Ventas
A18: Margen neto | B18: =Resultados!B31/Resultados!B4 | C18: ➜ Resultado del Ejercicio ÷ Ventas
A19: ROA (rentabilidad del activo) | B19: =Resultados!B31/Balance!B4 | C19: ➜ Resultado del Ejercicio ÷ Activo Total
A20: ROE (rentabilidad del patrimonio) | B20: =Resultados!B31/Balance!B53 | C20: ➜ Resultado del Ejercicio ÷ Patrimonio Neto
A21: GESTIÓN (rotaciones)
A22: Indicador | B22: Valor | C22: Cómo se construye (➜ magnitudes vinculadas)
A23: Rotación de cuentas por cobrar | B23: =Resultados!B4/Balance!B12 | C23: ➜ Ventas ÷ Créditos por ventas
A24: Días de cobranza (DSO) | B24: =Balance!B12/Resultados!B4*365 | C24: ➜ Créditos por ventas ÷ Ventas × 365
A25: Rotación de inventario | B25: =-Resultados!B7/Balance!B19 | C25: ➜ CMV ÷ Inventarios
A26: Días de inventario (DIO) | B26: =Balance!B19/(-Resultados!B7)*365 | C26: ➜ Inventarios ÷ CMV × 365
A27: Días de pago a proveedores (DPO) | B27: =Balance!B41/(-Resultados!B7)*365 | C27: ➜ Deudas comerciales ÷ CMV × 365
A28: Ciclo de conversión de caja | B28: =Balance!B12/Resultados!B4*365+Balance!B19/(-Resultados!B7)*365-Balance!B41/(-Resultados!B7)*365 | C28: ➜ DSO + DIO − DPO
A29: Rotación del activo | B29: =Resultados!B4/Balance!B4 | C29: ➜ Ventas ÷ Activo Total
A30: OPERATIVOS (creación de valor)
A31: Indicador | B31: Valor | C31: Cómo se construye (➜ magnitudes vinculadas)
A32: Margen EBIT | B32: =Resultados!B23/Resultados!B4 | C32: ➜ EBIT ÷ Ventas
A33: Margen EBITDA | B33: =Resultados!B20/Resultados!B4 | C33: ➜ EBITDA ÷ Ventas
A34: NOPAT (EBIT × (1 − 35%)) | B34: =_xlfn.LET(t,0.35,Resultados!B23*(1-t)) | C34: ➜ EBIT × (1 − tasa de impuesto)
A35: Capital invertido | B35: =(Balance!B12+Balance!B19-Balance!B41)+Balance!B24 | C35: ➜ (CxC + Inventario − Comerciales) + Activo No Corriente
A36: ROIC | B36: =_xlfn.LET(nopat,Resultados!B23*(1-0.35),ci,(Balance!B12+Balance!B19-Balance!B41)+Balance!B24,nopat/ci) | C36: ➜ NOPAT ÷ Capital invertido
A37: FINANCIEROS (riesgo de la deuda)
A38: Indicador | B38: Valor | C38: Cómo se construye (➜ magnitudes vinculadas)
A39: Cobertura de intereses | B39: =Resultados!B23/(-Resultados!B24) | C39: ➜ EBIT ÷ Intereses (resultados financieros)
A40: Intereses sobre EBIT | B40: =-Resultados!B24/Resultados!B23 | C40: ➜ Intereses ÷ EBIT
A41: Deuda financiera / EBITDA | B41: =(Balance!B37+Balance!B48-Balance!B41)/Resultados!B20 | C41: ➜ (Deuda corriente + no corriente − comerciales) ÷ EBITDA (aprox.)
...
